Workbook

Sheet はじめに
A1: 日本の感染症を知る：HIV/エイズ・梅毒・はしか・結核の状況
A3: 作成日 | B3: 2026年10月26日（この日までに国が公表した資料をもとにしています）
A4: 内容 | B4: 4つの感染症について、最新の人数、過去10年の動き、男女・年代・都道府県、2026年の途中経過、国の対策と、検査・予防・治療で使える公費の制度をまとめました。
A5: 使った資料 | B5: 国の公式資料だけを使いました（厚生労働省、国立健康危機管理研究機構〔JIHS〕）。HIV/エイズの年報は、厚生労働省のページから案内されている「エイズ予防情報ネット」（国の委託先）に置かれているものを使っています。HIV/エイズの「世界の動向」だけは、国連の機関（国連合同エイズ計画〔UNAIDS〕・国際移住機関〔IOM〕）の公式資料を使っています。公費の制度のうち結核の医療費助成の一部は、東京都の公式ページで確かめました。
A6: シートの説明 | B6: 「4つの比較」…4つの病気を1つの表で比べます。 「公費の支え」…検査・予防・治療で使える公費の制度の一覧と、病気ごとの説明、HIVの治療の自己負担の上限。 「HIV・エイズ」「梅毒」「はしか」「結核」…病気ごとの詳しい数字です。 「HIV・世界の動向」…世界全体と、日本と協力覚書を結んだ国のHIVの状況（UNAIDSの推計）、移住者とHIV、入国前の健康診断。 「見るときの注意」…数字を読むときに気をつけること。 「出典一覧」…すべての資料名とURL。
A7: 確定値 | B7: 国が1年分の届出を集計し直した数。
A8: 速報値 | B8: 毎週や3か月ごとに出る途中の数。あとから変わることがあります。表では黄色で示しています。
A9: 届出数 | B9: 医師が感染症と診断して保健所に届け出た数。検査を受けていない人などは入らないため、実際に感染している人の数とは同じではありません。
A10: 罹患率（りかんりつ） | B10: 人口10万人あたり、1年間に新しく病気になった人の数。人口の違う地域や年どうしを比べやすくなります。
A11: 公費（こうひ） | B11: 国や都道府県・市区町村が、税金などで費用を負担すること。

Sheet 4つの比較
A1: 4つの病気の比較
A2: 数字は各病気のシートから自動で読み込んでいます。前年比・10年前と比べた倍率・前年同期比はここで計算したものです。
A4: 病気 | B4: 数えているもの | C4: 最新の確定値の年 | D4: 最新の確定値 | E4: その前の年 | F4: 前年比 | G4: 10年前の年 | H4: 10年前の数 | I4: 10年前と比べて | J4: 2025年（速報値） | K4: 2026年の途中経過の期間 | L4: 2026年の途中経過 | M4: 前年の同じ時期 | N4: 前年同期比
A5: HIV/エイズ | B5: 新たに報告されたHIV感染者とエイズ患者の合計（件） | C5: =HIV・エイズ!A15 -> 2025 | D5: =HIV・エイズ!D15 -> 890 | E5: =HIV・エイズ!D14 -> 994 | F5: =D5/E5-1 -> -0.10462777 | G5: =HIV・エイズ!A6 -> 2016 | H5: =HIV・エイズ!D6 -> 1448 | I5: =D5/H5 -> 0.61464088 | J5: — | K5: =HIV・エイズ!B22 -> 2026年1〜6月ごろ（第1・第2四半期） | L5: =HIV・エイズ!C22 -> 477 | M5: =HIV・エイズ!D22 -> 423 | N5: =L5/M5-1 -> 0.12765957
A6: 梅毒 | B6: 医師が届け出た患者の数（人） | C6: =梅毒!A15 -> 2024 | D6: =梅毒!B15 -> 14829 | E6: =梅毒!B14 -> 15055 | F6: =D6/E6-1 -> -0.015011624 | G6: =梅毒!A6 -> 2015 | H6: =梅毒!B6 -> 2690 | I6: =D6/H6 -> 5.5126394 | J6: =梅毒!B16 -> 13530 | K6: =梅毒!B21 -> 2026年1月〜10月11日（第41週まで） | L6: =梅毒!C21 -> 8942 | M6: =梅毒!D21 -> 10985 | N6: =L6/M6-1 -> -0.18598088
A7: はしか（麻しん） | B7: 医師が届け出た患者の数（人） | C7: =はしか!A15 -> 2024 | D7: =はしか!B15 -> 45 | E7: =はしか!B14 -> 28 | F7: =D7/E7-1 -> 0.60714286 | G7: =はしか!A6 -> 2015 | H7: =はしか!B6 -> 35 | I7: =D7/H7 -> 1.2857143 | J7: =はしか!B16 -> 265 | K7: =はしか!B21 -> 2026年1月〜10月11日（第41週まで） | L7: =はしか!C21 -> 579 | M7: =はしか!D21 -> 231 | N7: =L7/M7-1 -> 1.5064935
A8: 結核 | B8: 新たに登録された結核患者の数（人） | C8: =結核!A15 -> 2025 | D8: =結核!B15 -> 9899 | E8: =結核!B14 -> 10051 | F8: =D8/E8-1 -> -0.015122873 | G8: =結核!A6 -> 2016 | H8: =結核!B6 -> 17625 | I8: =D8/H8 -> 0.56164539 | J8: — | K8: =結核!B20 -> 2026年1月〜10月11日（第41週まで） | L8: =結核!C20 -> 11543 | M8: =結核!D20 -> 11145 | N8: =L8/M8-1 -> 0.035711081
A10: ・最新の確定値が出ている年は病気ごとに違います（HIV/エイズと結核は2025年、梅毒とはしかは2024年）。
A11: ・「10年前の年」は、最新の確定値の年から数えて10年分の最初の年です。
A12: ・2026年の途中経過は速報値で、病気によって期間が違います。結核の途中経過は医師の届出の数で、発病していない感染者も含むため、年報の「新登録患者数」とは比べられません。
A13: ・黄色のセルは速報値です。

Sheet 公費の支え
A1: 公費で受けられる支え（検査・予防・治療）
A2: 公費とは、国や都道府県・市区町村が税金などで費用を負担することです。4つの病気について、検査・予防・治療の場面で使える主な公費の制度を、国の法律や資料（結核の医療費の一部は東京都の資料）からまとめました。2026年10月26日時点の内容です。
A4: ひと目でわかる一覧
A5: 病気 | B5: 場面 | C5: 目安 | D5: 内容 | E5: 出典ID
A6: HIV/エイズ | B6: 検査・健診 | C6: 公費あり | D6: 保健所などで、名前を伝えずに無料で検査を受けられる。妊婦健診でも妊娠の初めごろに1回検査する。 | E6: HIV-14
A7: HIV/エイズ | B7: 予防 | C7: 公費なし | D7: 予防薬（PrEP）は2024年に承認されたが、費用を公費で出す仕組みは国の資料に書かれていない。 | E7: 公費-6
A8: HIV/エイズ | B8: 治療 | C8: 公費あり | D8: 身体障害者手帳（免疫機能障害）があれば「自立支援医療」が使え、1か月の自己負担は所得に応じて0円〜2万円まで。 | E8: 公費-5
A9: 梅毒 | B9: 検査・健診 | C9: 公費あり | D9: 地域によって、保健所などで名前を伝えずに無料で検査を受けられる。妊婦健診でも妊娠の初めごろに1回検査する。 | E9: 梅毒-11
A10: 梅毒 | B10: 予防 | C10: 公費なし | D10: 予防の基本はコンドームを正しく使うこと。予防のための公費の制度は、国の資料には見当たらない。 | E10: 梅毒-11
A11: 梅毒 | B11: 治療 | C11: 公費なし | D11: 治療費を公費で出す感染症法の制度はなく、ふつうの健康保険で治療を受ける。 | E11: 公費-1
A12: はしか（麻しん） | B12: 検査・健診 | C12: 公費なし | D12: 自分から申し込んで受ける公費の検査は、国の資料には見当たらない。はしかと診断された人の確認の遺伝子検査は、都道府県などの地方衛生研究所が行う。 | E12: はしか-15
A13: はしか（麻しん） | B13: 予防 | C13: 公費あり | D13: 子どもの定期接種2回（1歳の1年間と、小学校に入る前の1年間）は公費。大人は定期接種の対象ではない（任意接種）。 | E13: 公費-8
A14: はしか（麻しん） | B14: 治療 | C14: 公費なし | D14: 治療費を公費で出す感染症法の制度はなく、ふつうの健康保険で治療を受ける。 | E14: 公費-1
A15: 結核 | B15: 検査・健診 | C15: 公費あり | D15: 保健所などから健康診断を勧められた人（患者と接した人など）の健診は、費用を都道府県などが出す。 | E15: 公費-1
A16: 結核 | B16: 予防 | C16: 公費あり | D16: 赤ちゃんのBCGワクチンの定期接種は公費。 | E16: 公費-8
A17: 結核 | B17: 治療 | C17: 公費あり | D17: 申請すると治療費の95%を健康保険と公費で負担し、自己負担は5%。入院の勧告を受けたときは原則0円（所得の多い世帯は1か月2万円まで）。 | E17: 公費-2
A18: 「公費なし」は、その場面で使える国の公費の制度が、国の法律や資料に見当たらないという意味です。
A20: 治療費の公費のしくみ（感染症法）
A21: 1. 感染症法で治療費を公費で負担するのは、入院の勧告を受けた患者（第37条）と、結核の患者（第37条の2）。どちらも健康保険が先に使われ、残りを公費で負担する（第39条）。（出典 公費-1）
A22: 2. 入院の勧告ができるのは1類・2類感染症などで、結核は2類感染症。HIV/エイズ（後天性免疫不全症候群）・梅毒・はしか（麻しん）は5類感染症のため、入院の勧告や、それにともなう治療費の公費負担の対象ではない（第6条・第19条・第26条）。（出典 公費-1）
A24: HIV/エイズ
A25: 1. 【検査】保健所や自治体の検査所では、名前や住所を伝えずに無料でHIV検査を受けられる。（出典 HIV-14）
A26: 2. 【検査】妊婦健診では、妊娠の初めごろに1回HIVの検査をすることが国の基準に入っていて、市区町村が14回分ほどの健診費用を公費で出している。ただし、健診で自己負担が0円の人は約3割で、3万円以上かかる人も約1割いるなど、地域や医療機関によって差がある。（出典 公費-7）
A27: 3. 【予防】HIVを防ぐ薬（PrEP、曝露前予防）は、2024年8月28日に国内で承認された（ツルバダ配合錠）。国の資料には、この薬の費用を公費で出す仕組みは書かれていない。（出典 公費-6）
A28: 4. 【予防】2025年11月に改正された国のエイズ予防指針では、PrEPは「感染予防に有用な手段の一つ」とされ、さらに検討を進めることが重要とされている。（出典 HIV-15）
A29: 5. 【治療】HIVによって免疫の働きが落ちた状態（免疫機能障害）は、市区町村が行う「自立支援医療（更生医療）」の対象で、抗HIV薬による治療（抗HIV療法）などHIV感染症の治療に使える。（出典 公費-4）
A30: 6. 【治療】更生医療を使えるのは、身体障害者手帳を受けた18歳以上の人。（出典 公費-3）
A31: 7. 【治療】自己負担は原則1割。HIV（免疫機能障害）は「費用が高い治療を長く続ける人（重度かつ継続）」に入るため、所得に応じて1か月の自己負担に上限がつき、0円〜2万円になる（下の表）。（出典 公費-5）
A33: HIVの治療：自立支援医療の1か月の自己負担の上限
A34: 所得の区分（健康保険の世帯） | D34: 1か月の上限（円） | E34: 出典ID
A35: 生活保護の世帯 | D35: 0 | E35: 公費-5
A36: 住民税がかからない世帯（本人の年収が82.65万円以下） | D36: 2500 | E36: 公費-5
A37: 住民税がかからない世帯（上記以外） | D37: 5000 | E37: 公費-5
A38: 住民税の所得割が3万3千円未満（年収約290〜400万円未満） | D38: 5000 | E38: 公費-5
A39: 住民税の所得割が3万3千円以上23万5千円未満（年収約400〜833万円未満） | D39: 10000 | E39: 公費-5
A40: 住民税の所得割が23万5千円以上（年収約833万円以上） | D40: 20000 | E40: 公費-5
A41: 注：HIV（免疫機能障害）は「重度かつ継続」に入るため、この上限になります。所得の区分は健康保険の世帯ごとに決まり、年収は夫婦と障害のある子の3人世帯の目安です。医療費の1割がこの上限より少ないときは、1割を払います。いちばん下の段（2万円）は、2027年3月31日までの特例です。
A43: 梅毒
A44: 1. 【検査】地域によっては、保健所などで名前を伝えずに無料で梅毒の検査を受けられる。（出典 梅毒-11）
A45: 2. 【検査】妊婦健診では、妊娠の初めごろに1回梅毒の検査をすることが国の基準に入っていて、市区町村が14回分ほどの健診費用を公費で出している（自己負担は地域や医療機関によって差がある）。（出典 公費-7）
...

Sheet HIV・エイズ
A1: HIV/エイズ
A2: 数え方：医師が診断後7日以内に保健所を通じて都道府県知事へ届け出た件数（感染症法の5類感染症・全数把握「後天性免疫不全症候群」）を、厚生労働省エイズ動向委員会が報告年ごとに集計したもの。「HIV感染者」は無症候性キャリア等として届け出られた人、「エイズ患者」は初めて届け出られた時点で既にエイズと診断されていた人（HIV感染者として報告済みの人が後にエイズを発症した分は含まない）。血液凝固因子製剤による感染例（薬害）は含まない。単位は件（≒人）。
A4: 年ごとの推移
A5: 年 | B5: HIV感染者 | C5: エイズ患者 | D5: 合計 | E5: 前年比（合計） | F5: 区分 | G5: 出典ID
A6: 2016 | B6: 1011 | C6: 437 | D6: =B6+C6 -> 1448 | E6: — | F6: 確定 | G6: HIV-4
A7: 2017 | B7: 976 | C7: 413 | D7: =B7+C7 -> 1389 | E7: =IF(D6="","",D7/D6-1) -> -0.040745856 | F7: 確定 | G7: HIV-4
A8: 2018 | B8: 940 | C8: 377 | D8: =B8+C8 -> 1317 | E8: =IF(D7="","",D8/D7-1) -> -0.051835853 | F8: 確定 | G8: HIV-4
A9: 2019 | B9: 903 | C9: 333 | D9: =B9+C9 -> 1236 | E9: =IF(D8="","",D9/D8-1) -> -0.061503417 | F9: 確定 | G9: HIV-4
A10: 2020 | B10: 750 | C10: 345 | D10: =B10+C10 -> 1095 | E10: =IF(D9="","",D10/D9-1) -> -0.11407767 | F10: 確定 | G10: HIV-4
A11: 2021 | B11: 742 | C11: 315 | D11: =B11+C11 -> 1057 | E11: =IF(D10="","",D11/D10-1) -> -0.034703196 | F11: 確定 | G11: HIV-4
A12: 2022 | B12: 632 | C12: 252 | D12: =B12+C12 -> 884 | E12: =IF(D11="","",D12/D11-1) -> -0.16367077 | F12: 確定 | G12: HIV-4
A13: 2023 | B13: 669 | C13: 291 | D13: =B13+C13 -> 960 | E13: =IF(D12="","",D13/D12-1) -> 0.085972851 | F13: 確定 | G13: HIV-4
A14: 2024 | B14: 662 | C14: 332 | D14: =B14+C14 -> 994 | E14: =IF(D13="","",D14/D13-1) -> 0.035416667 | F14: 確定 | G14: HIV-4
A15: 2025 | B15: 624 | C15: 266 | D15: =B15+C15 -> 890 | E15: =IF(D14="","",D15/D14-1) -> -0.10462777 | F15: 確定 | G15: HIV-4
A16: 黄色の行は速報値（あとで変わることがあります）。それ以外は確定値。前年比はこの表で計算したもの。
A18: 2026年の途中経過（速報）
A19: 指標 | B19: 期間 | C19: 2026年 | D19: 前年同期 | E19: 前年同期比 | F19: 区分 | G19: 出典ID
A20: HIV感染者 | B20: 2026年1〜6月ごろ（第1・第2四半期） | C20: 338 | D20: 304 | E20: =C20/D20-1 -> 0.11184211 | F20: 速報 | G20: HIV-10
A21: エイズ患者 | B21: 2026年1〜6月ごろ（第1・第2四半期） | C21: 139 | D21: 119 | E21: =C21/D21-1 -> 0.16806723 | F21: 速報 | G21: HIV-10
A22: 合計 | B22: 2026年1〜6月ごろ（第1・第2四半期） | C22: 477 | D22: 423 | E22: =C22/D22-1 -> 0.12765957 | F22: 速報 | G22: HIV-10
A23: 期間のくわしい説明：2026年第1・第2四半期（2025年12月29日〜2026年6月28日の報告分。おおむね2026年1〜6月）
A24: 注：資料には四半期ごとの値しかないため、第1・第2四半期の値を足したもの（HIV 173+165、エイズ 52+87、前年同期 HIV 148+156・エイズ 52+67）。検算：2026年第2四半期時点の累計（HIV-11 表2）HIV 26,156−2025年末累計25,818＝338、エイズ 11,586−11,447＝139 で一致。前年同期の値は2026年9月の委員長コメントに載っている2025年当時の四半期速報値。
A26: 男女別（2025年）
A27: 区分 | B27: 男性 | C27: 女性 | D27: 出典ID
A28: HIV感染者 | B28: 596 | C28: 28 | D28: HIV-3
A29: エイズ患者 | B29: 248 | C29: 18 | D29: HIV-3
A30: 注：資料の記述：HIV感染者とエイズ患者を合わせた新規報告の約95%を男性が占める（HIV-2）。
A32: 年代別（2025年）
A33: 区分 | B33: HIV感染者 | C33: エイズ患者 | D33: 出典ID
A34: 10歳未満 | B34: 1 | C34: 0 | D34: HIV-5
A35: 10-14歳 | B35: 0 | C35: 0 | D35: HIV-5
A36: 15-19歳 | B36: 8 | C36: 0 | D36: HIV-5
A37: 20-24歳 | B37: 101 | C37: 10 | D37: HIV-5
A38: 25-29歳 | B38: 118 | C38: 28 | D38: HIV-5
A39: 30-34歳 | B39: 126 | C39: 36 | D39: HIV-5
A40: 35-39歳 | B40: 90 | C40: 37 | D40: HIV-5
A41: 40-44歳 | B41: 55 | C41: 41 | D41: HIV-5
A42: 45-49歳 | B42: 36 | C42: 28 | D42: HIV-5
A43: 50-54歳 | B43: 32 | C43: 35 | D43: HIV-5
A44: 55-59歳 | B44: 24 | C44: 19 | D44: HIV-5
...

Sheet HIV・世界の動向
A1: HIV/エイズ 世界の動向
A2: 数え方：国連合同エイズ計画（UNAIDS）が各国と一緒に作った推計値（2026年版の推計で、2025年の数字）。届出で数えた数ではなく、調査や報告のデータをもとに計算した「おおよその数」です。「感染している人」はHIVとともに生きている人の数、「新たな感染」はその1年間に新たにHIVに感染した人、「エイズによる死亡」はその1年間にエイズに関連する病気で亡くなった人の推計です。
A4: 世界と地域（2025年）
A5: 名前 | B5: 区分 | C5: 協力覚書 | D5: 感染している人 | E5: 感染している人（下限） | F5: 感染している人（上限） | G5: 15〜49歳の感染率（%） | H5: 新たな感染 | I5: 新たな感染の増減（2010年比・%） | J5: エイズによる死亡 | K5: 死亡の増減（2010年比・%） | L5: 感染を知っている人（%） | M5: 治療を受けている人（%） | N5: ウイルスが抑えられている人（%） | O5: 出典ID
A6: 世界 | B6: 世界 | D6: 41000000 | E6: 35300000 | F6: 47500000 | G6: 0.7 | H6: 1200000 | I6: -42 | J6: 570000 | K6: -57 | L6: 88 | M6: 78 | N6: 74 | O6: 世界-2
A7: アジア太平洋 | B7: 地域 | D7: 7100000 | E7: 6300000 | F7: 8000000 | G7: 0.2 | H7: 280000 | I7: -21 | J7: 120000 | K7: -59 | L7: 81 | M7: 72 | N7: 69 | O7: 世界-1
A8: 東欧・中央アジア | B8: 地域 | D8: 2000000 | E8: 1800000 | F8: 2200000 | G8: 1.1 | H8: 120000 | I8: 17 | J8: 43000 | K8: 11 | L8: 83 | M8: 56 | N8: 48 | O8: 世界-1
A10: 日本と協力覚書を結んだ国（2025年、感染している人の多い順）
A11: 名前 | B11: 区分 | C11: 協力覚書 | D11: 感染している人 | E11: 感染している人（下限） | F11: 感染している人（上限） | G11: 15〜49歳の感染率（%） | H11: 新たな感染 | I11: 新たな感染の増減（2010年比・%） | J11: エイズによる死亡 | K11: 死亡の増減（2010年比・%） | L11: 感染を知っている人（%） | M11: 治療を受けている人（%） | N11: ウイルスが抑えられている人（%） | O11: 出典ID
A12: インド | B12: 国 | C12: 特定技能・技能実習 | D12: 2600000 | E12: 2100000 | F12: 3100000 | G12: 0.2 | H12: 60000 | I12: -52 | J12: 25000 | K12: -86 | L12: 88 | M12: 77 | N12: 74 | O12: 世界-1
A13: タイ | B13: 国 | C13: 特定技能・技能実習 | D13: 620000 | E13: 560000 | F13: 690000 | G13: 1.1 | H13: 7300 | I13: -66 | J13: 8400 | K13: -80 | L13: 90 | M13: 82 | N13: 81 | O13: 世界-1
A14: インドネシア | B14: 国 | C14: 特定技能・技能実習 | D14: 560000 | E14: 500000 | F14: 610000 | G14: 0.3 | H14: 21000 | I14: -57 | J14: 18000 | K14: 29 | L14: 67 | M14: 48 | N14: 45 | O14: 世界-1
A15: パキスタン | B15: 国 | C15: 特定技能・技能実習 | D15: 340000 | E15: 310000 | F15: 370000 | G15: 0.2 | H15: 44000 | I15: 222 | J15: 14000 | K15: 553 | L15: 25 | M15: 18 | N15: — | O15: 世界-1
A16: ミャンマー | B16: 国 | C16: 特定技能・技能実習 | D16: 310000 | E16: 270000 | F16: 340000 | G16: 0.9 | H16: 9500 | I16: -43 | J16: 4400 | K16: -63 | L16: 84 | M16: 73 | N16: 70 | O16: 世界-1
A17: ベトナム | B17: 国 | C17: 特定技能・技能実習 | D17: 270000 | E17: 240000 | F17: 310000 | G17: 0.4 | H17: 6100 | I17: -58 | J17: 4100 | K17: -14 | L17: 94 | M17: 75 | N17: 72 | O17: 世界-1
A18: フィリピン | B18: 国 | C18: 特定技能・技能実習 | D18: 250000 | E18: 210000 | F18: 290000 | G18: 0.4 | H18: 34000 | I18: 627 | J18: 2700 | K18: 713 | L18: 62 | M18: 41 | N18: 40 | O18: 世界-1
A19: マレーシア | B19: 国 | C19: 特定技能 | D19: 85000 | E19: 76000 | F19: 94000 | G19: 0.3 | H19: 2900 | I19: -53 | J19: 2000 | K19: -41 | L19: 66 | M19: 63 | N19: 55 | O19: 世界-1
A20: カンボジア | B20: 国 | C20: 特定技能・技能実習 | D20: 76000 | E20: 64000 | F20: 87000 | G20: 0.5 | H20: 960 | I20: -59 | J20: 1000 | K20: -40 | L20: 95 | M20: 95 | N20: 93 | O20: 世界-1
A21: ウズベキスタン | B21: 国 | C21: 特定技能・技能実習 | D21: 63000 | E21: 51000 | F21: 81000 | G21: 0.2 | H21: — | I21: — | J21: — | K21: — | L21: 84 | M21: 75 | N21: 68 | O21: 世界-1
A22: ネパール | B22: 国 | C22: 特定技能・技能実習 | D22: 35000 | E22: 31000 | F22: 38000 | G22: 0.1 | H22: 550 | I22: -79 | J22: 570 | K22: -75 | L22: 92 | M22: 79 | N22: 77 | O22: 世界-1
A23: ラオス | B23: 国 | C23: 特定技能・技能実習 | D23: 23000 | E23: 20000 | F23: 25000 | G23: 0.5 | H23: 1300 | I23: 11 | J23: <500 | K23: 36 | L23: 75 | M23: 64 | N23: 63 | O23: 世界-1
A24: バングラデシュ | B24: 国 | C24: 特定技能・技能実習 | D24: 19000 | E24: 17000 | F24: 21000 | G24: <0.1 | H24: 1500 | I24: 84 | J24: 570 | K24: 135 | L24: 63 | M24: 44 | N24: 40 | O24: 世界-1
A25: タジキスタン | B25: 国 | C25: 特定技能 | D25: 16000 | E25: 14000 | F25: 19000 | G25: 0.2 | H25: <500 | I25: -69 | J25: <500 | K25: -58 | L25: 83 | M25: 76 | N25: 70 | O25: 世界-1
A26: キルギス | B26: 国 | C26: 特定技能 | D26: 14000 | E26: 13000 | F26: 15000 | G26: 0.3 | H26: 1100 | I26: 106 | J26: <500 | K26: 10 | L26: 77 | M26: 55 | N26: — | O26: 世界-1
A27: フィジー | B27: 国 | C27: 技能実習 | D27: 9100 | E27: 7200 | F27: 12000 | G27: 1.6 | H27: 1700 | I27: 1121 | J27: <500 | K27: 1172 | L27: 39 | M27: 22 | N27: — | O27: 世界-1
A28: スリランカ | B28: 国 | C28: 特定技能・技能実習 | D28: 8700 | E28: 7800 | F28: 9600 | G28: <0.1 | H28: 860 | I28: 135 | J28: <200 | K28: -47 | L28: 66 | M28: 52 | N28: 46 | O28: 世界-1
A29: 東ティモール | B29: 国 | C29: 技能実習 | D29: 2200 | E29: 1900 | F29: 2600 | G29: 0.3 | H29: <200 | I29: 26 | J29: <100 | K29: -30 | L29: 89 | M29: 66 | N29: 46 | O29: 世界-1
A30: ブータン | B30: 国 | C30: 技能実習 | D30: 1200 | E30: 1000 | F30: 1400 | G30: 0.2 | H30: <100 | I30: 1 | J30: <100 | K30: -49 | L30: 82 | M30: 69 | N30: 62 | O30: 世界-1
A31: モンゴル | B31: 国 | C31: 特定技能・技能実習 | D31: 700 | E31: 620 | F31: 780 | G31: <0.1 | H31: <100 | I31: 5 | J31: <100 | K31: 31 | L31: — | M31: 42 | N31: — | O31: 世界-1
A33: 「<100」は100人未満、「—」はUNAIDSに数字がないことを表します。増減（2010年比・%）と割合（%）はUNAIDSの資料に書かれた値です。
A35: 日本の協力覚書（特定技能・技能実習）
A36: 1. 日本は、外国人材の受け入れについて、送り出す国と「協力覚書」（MOC）を作っています。「特定技能」では17か国です（公表順に、フィリピン、カンボジア、ネパール、ミャンマー、モンゴル、スリランカ、インドネシア、ベトナム、バングラデシュ、ウズベキスタン、パキスタン、タイ、インド、マレーシア、ラオス、キルギス、タジキスタン）。（出典 世界-3）
A37: 2. 特定技能でいちばん新しいのはタジキスタンで、2024年8月8日に協力覚書に署名しました。（出典 世界-4）
A38: 3. 「技能実習」でも17か国と協力覚書があります。新しい順に、フィジー（2025年11月13日）、東ティモール（2024年10月8日）、ネパール、インドネシア、タイ、パキスタン、ウズベキスタン、ブータン、ミャンマー、スリランカ、バングラデシュ、モンゴル、ラオス、フィリピン、インド、カンボジア、ベトナム（2017年6月6日）です。（出典 世界-5）
A39: 4. 両方の制度で覚書がある国は14か国。技能実習だけの国はブータン・東ティモール・フィジー、特定技能だけの国はマレーシア・キルギス・タジキスタンです。このページでは、合わせて20か国を載せています。
A41: 移住者とHIV（国連の機関の見方）
A42: 1. 国際移住機関（IOM）は、移住すること自体でHIVにかかりやすくなるわけではないとしつつ、多くの場合、移住者は社会・文化・経済・環境の面で弱い立場に置かれ、HIVにかかりやすくなると説明しています。（出典 世界-10）
A43: 2. IOMは、医療や福祉を受けにくいこと、移住者とHIVへの偏見や差別、強制的な検査やHIVとともに生きる人の移動を制限する法律が、移住者のHIVへの弱さを増やし続けていると指摘しています。（出典 世界-10）
A44: 3. IOMは、HIVの検査は本人の意思で受けるもので、秘密が守られ、相談の支えがあるべきだとしています。また、陽性とわかった人は、国籍や在留資格にかかわらず質の高い医療を受けられるべきだとしています（2018年の世界エイズデーの発表）。（出典 世界-11）
A45: 4. 同じ発表でIOMは各国に、HIVを理由とした入国制限の見直しと、誰もが必要な医療を受けられる仕組み（ユニバーサル・ヘルス・カバレッジ）を進めることを求めています。（出典 世界-11）
...

Sheet 梅毒
A1: 梅毒
A2: 数え方：医師が保健所に届け出た梅毒の患者数（症状のない感染者＝無症候、母子感染の先天梅毒を含む）。感染症法の5類感染症・全数把握（診断した医師は7日以内に届け出る義務あり）。年は診断された年で集計。
A4: 年ごとの推移
A5: 年 | B5: 合計 | C5: 男性 | D5: 女性 | E5: 前年比（合計） | F5: 区分 | G5: 出典ID
A6: 2015 | B6: 2690 | C6: 1930 | D6: 760 | E6: — | F6: 確定 | G6: 梅毒-1
A7: 2016 | B7: 4575 | C7: 3189 | D7: 1386 | E7: =IF(B6="","",B7/B6-1) -> 0.70074349 | F7: 確定 | G7: 梅毒-1
A8: 2017 | B8: 5826 | C8: 3931 | D8: 1895 | E8: =IF(B7="","",B8/B7-1) -> 0.27344262 | F8: 確定 | G8: 梅毒-1
A9: 2018 | B9: 7007 | C9: 4591 | D9: 2416 | E9: =IF(B8="","",B9/B8-1) -> 0.20271198 | F9: 確定 | G9: 梅毒-1
A10: 2019 | B10: 6642 | C10: 4387 | D10: 2255 | E10: =IF(B9="","",B10/B9-1) -> -0.052090766 | F10: 確定 | G10: 梅毒-1
A11: 2020 | B11: 5867 | C11: 3902 | D11: 1965 | E11: =IF(B10="","",B11/B10-1) -> -0.11668172 | F11: 確定 | G11: 梅毒-1
A12: 2021 | B12: 7978 | C12: 5261 | D12: 2717 | E12: =IF(B11="","",B12/B11-1) -> 0.3598091 | F12: 確定 | G12: 梅毒-1
A13: 2022 | B13: 13221 | C13: 8701 | D13: 4519 | E13: =IF(B12="","",B13/B12-1) -> 0.65718225 | F13: 確定 | G13: 梅毒-1
A14: 2023 | B14: 15055 | C14: 9710 | D14: 5345 | E14: =IF(B13="","",B14/B13-1) -> 0.13871871 | F14: 確定 | G14: 梅毒-1
A15: 2024 | B15: 14829 | C15: 9504 | D15: 5324 | E15: =IF(B14="","",B15/B14-1) -> -0.015011624 | F15: 確定 | G15: 梅毒-1
A16: 2025 | B16: 13530 | C16: 8565 | D16: 4963 | E16: =IF(B15="","",B16/B15-1) -> -0.087598624 | F16: 速報 | G16: 梅毒-8
A17: 黄色の行は速報値（あとで変わることがあります）。それ以外は確定値。前年比はこの表で計算したもの。
A19: 2026年の途中経過（速報）
A20: 指標 | B20: 期間 | C20: 2026年 | D20: 前年同期 | E20: 前年同期比 | F20: 区分 | G20: 出典ID
A21: 合計 | B21: 2026年1月〜10月11日（第41週まで） | C21: 8942 | D21: 10985 | E21: =C21/D21-1 -> -0.18598088 | F21: 速報 | G21: 梅毒-5
A22: 期間のくわしい説明：2026年第41週（〜2026-10-11）まで（2026-10-14集計）
A24: 男女別（2024年）
A25: 区分 | B25: 男性 | C25: 女性 | D25: 出典ID
A26: 届出数 | B26: 9504 | C26: 5324 | D26: 梅毒-3
A28: 年代別（2024年）
A29: 区分 | B29: 男性 | C29: 女性 | D29: 合計 | E29: 出典ID
A30: 0歳 | B30: 12 | C30: 18 | D30: 30 | E30: 梅毒-3
A31: 1-4歳 | B31: 0 | C31: 0 | D31: 0 | E31: 梅毒-3
A32: 5-9歳 | B32: 0 | C32: 0 | D32: 0 | E32: 梅毒-3
A33: 10-14歳 | B33: 0 | C33: 7 | D33: 7 | E33: 梅毒-3
A34: 15-19歳 | B34: 175 | C34: 452 | D34: 627 | E34: 梅毒-3
A35: 20-24歳 | B35: 954 | C35: 1951 | D35: 2905 | E35: 梅毒-3
A36: 25-29歳 | B36: 1176 | C36: 1096 | D36: 2272 | E36: 梅毒-3
A37: 30-34歳 | B37: 1053 | C37: 466 | D37: 1519 | E37: 梅毒-3
A38: 35-39歳 | B38: 1089 | C38: 317 | D38: 1406 | E38: 梅毒-3
A39: 40-44歳 | B39: 1139 | C39: 270 | D39: 1409 | E39: 梅毒-3
A40: 45-49歳 | B40: 1128 | C40: 255 | D40: 1383 | E40: 梅毒-3
A41: 50-54歳 | B41: 998 | C41: 195 | D41: 1193 | E41: 梅毒-3
... A45: 70歳以上 | B45: 327 | C45: 118 | D45: 445 | E45: 梅毒-3
A47: 都道府県別 上位5（2024年、人数の多い順）
A48: 区分 | B48: 順位 | C48: 人数 | D48: 人口10万対 | E48: 出典ID
...

Sheet はしか
A1: はしか（麻しん）
A2: 数え方：医師が麻しんと診断したときに保健所へ届け出た患者の数（感染症法の5類感染症・全数把握。麻しんは2008年1月から全数把握）。年は診断週にもとづく区切り。確定値は感染症発生動向調査の年報集計値、速報は週報の速報値（暫定値）で、あとから修正されることがある。
A4: 年ごとの推移
A5: 年 | B5: 届出数 | C5: 前年比（届出数） | D5: 区分 | E5: 出典ID
A6: 2015 | B6: 35 | C6: — | D6: 確定 | E6: はしか-1
A7: 2016 | B7: 165 | C7: =IF(B6="","",B7/B6-1) -> 3.7142857 | D7: 確定 | E7: はしか-1
A8: 2017 | B8: 186 | C8: =IF(B7="","",B8/B7-1) -> 0.12727273 | D8: 確定 | E8: はしか-1
A9: 2018 | B9: 279 | C9: =IF(B8="","",B9/B8-1) -> 0.5 | D9: 確定 | E9: はしか-1
A10: 2019 | B10: 744 | C10: =IF(B9="","",B10/B9-1) -> 1.6666667 | D10: 確定 | E10: はしか-1
A11: 2020 | B11: 10 | C11: =IF(B10="","",B11/B10-1) -> -0.98655914 | D11: 確定 | E11: はしか-1
A12: 2021 | B12: 6 | C12: =IF(B11="","",B12/B11-1) -> -0.4 | D12: 確定 | E12: はしか-1
A13: 2022 | B13: 6 | C13: =IF(B12="","",B13/B12-1) -> 0 | D13: 確定 | E13: はしか-1
A14: 2023 | B14: 28 | C14: =IF(B13="","",B14/B13-1) -> 3.6666667 | D14: 確定 | E14: はしか-1
A15: 2024 | B15: 45 | C15: =IF(B14="","",B15/B14-1) -> 0.60714286 | D15: 確定 | E15: はしか-1
A16: 2025 | B16: 265 | C16: =IF(B15="","",B16/B15-1) -> 4.8888889 | D16: 速報 | E16: はしか-7
A17: 黄色の行は速報値（あとで変わることがあります）。それ以外は確定値。前年比はこの表で計算したもの。
A19: 2026年の途中経過（速報）
A20: 指標 | B20: 期間 | C20: 2026年 | D20: 前年同期 | E20: 前年同期比 | F20: 区分 | G20: 出典ID
A21: 届出数 | B21: 2026年1月〜10月11日（第41週まで） | C21: 579 | D21: 231 | E21: =C21/D21-1 -> 1.5064935 | F21: 速報 | G21: はしか-7
A22: 期間のくわしい説明：2026年第41週まで（診断日 2025-12-29〜2026-10-11、2026年10月14日現在）
A23: 注：2025年第1〜41週（診断日 2024-12-30〜2025-10-12、2025年10月15日現在の速報値。出典はしか-8）
A25: 男女別（2024年）
A26: 区分 | B26: 男性 | C26: 女性 | D26: 出典ID
A27: 届出数 | B27: 30 | C27: 15 | D27: はしか-2
A29: 年代別（2024年）
A30: 区分 | B30: 届出数 | C30: 出典ID
A31: 0歳 | B31: 6 | C31: はしか-2
A32: 1-4歳 | B32: 1 | C32: はしか-2
A33: 5-9歳 | B33: 1 | C33: はしか-2
A34: 10-14歳 | B34: 1 | C34: はしか-2
A35: 15-19歳 | B35: 7 | C35: はしか-2
A36: 20-24歳 | B36: 6 | C36: はしか-2
A37: 25-29歳 | B37: 8 | C37: はしか-2
A38: 30-34歳 | B38: 6 | C38: はしか-2
A39: 35-39歳 | B39: 2 | C39: はしか-2
A40: 40-44歳 | B40: 3 | C40: はしか-2
A41: 45-49歳 | B41: 3 | C41: はしか-2
A42: 50-54歳 | B42: 1 | C42: はしか-2
... A46: 70歳以上 | B46: 0 | C46: はしか-2
A48: 都道府県別 上位5（2024年、人数の多い順）
...

Sheet 結核
A1: 結核
A2: 数え方：その年（1月1日〜12月31日）に全国の保健所で新たに登録された結核患者の数（新登録結核患者数）と、人口10万人あたりの人数（罹患率）。発病していない感染者（潜在性結核感染症＝LTBI）は含まない。出典は厚生労働省「結核登録者情報調査年報集計結果」（保健所が感染症サーベイランスシステム上の結核登録者情報システムに入力したデータの年間集計）。結核は感染症法の2類感染症。
A4: 年ごとの推移
A5: 年 | B5: 新登録患者数 | C5: 罹患率（人口10万対） | D5: 前年比（新登録患者数） | E5: 区分 | F5: 出典ID
A6: 2016 | B6: 17625 | C6: 13.9 | D6: — | E6: 確定 | F6: 結核-1
A7: 2017 | B7: 16789 | C7: 13.3 | D7: =IF(B6="","",B7/B6-1) -> -0.047432624 | E7: 確定 | F7: 結核-1
A8: 2018 | B8: 15590 | C8: 12.3 | D8: =IF(B7="","",B8/B7-1) -> -0.071415808 | E8: 確定 | F8: 結核-1
A9: 2019 | B9: 14460 | C9: 11.5 | D9: =IF(B8="","",B9/B8-1) -> -0.07248236 | E9: 確定 | F9: 結核-1
A10: 2020 | B10: 12739 | C10: 10.1 | D10: =IF(B9="","",B10/B9-1) -> -0.11901798 | E10: 確定 | F10: 結核-1
A11: 2021 | B11: 11519 | C11: 9.2 | D11: =IF(B10="","",B11/B10-1) -> -0.095768899 | E11: 確定 | F11: 結核-1
A12: 2022 | B12: 10235 | C12: 8.2 | D12: =IF(B11="","",B12/B11-1) -> -0.11146801 | E12: 確定 | F12: 結核-1
A13: 2023 | B13: 10096 | C13: 8.1 | D13: =IF(B12="","",B13/B12-1) -> -0.01358085 | E13: 確定 | F13: 結核-1
A14: 2024 | B14: 10051 | C14: 8.1 | D14: =IF(B13="","",B14/B13-1) -> -0.0044572108 | E14: 確定 | F14: 結核-1
A15: 2025 | B15: 9899 | C15: 8 | D15: =IF(B14="","",B15/B14-1) -> -0.015122873 | E15: 確定 | F15: 結核-1
A16: 黄色の行は速報値（あとで変わることがあります）。それ以外は確定値。前年比はこの表で計算したもの。
A18: 2026年の途中経過（速報）
A19: 指標 | B19: 期間 | C19: 2026年 | D19: 前年同期 | E19: 前年同期比 | F19: 区分 | G19: 出典ID
A20: 届出数（発病していない感染者も含む） | B20: 2026年1月〜10月11日（第41週まで） | C20: 11543 | D20: 11145 | E20: =C20/D20-1 -> 0.035711081 | F20: 速報 | G20: 結核-4
A21: 期間のくわしい説明：2026年第41週（10月5日〜10月11日）までの累積（2026年10月14日集計）
A22: 注：感染症法にもとづく医師の届出の数（週報の速報値）で、年報の「新登録結核患者数」とは数え方が違うため直接比べられない。届出の対象には患者のほか、発病していない感染者で治療が必要な人（潜在性結核感染症）や疑似症患者も含まれる（結核-13）。参考までに2024年の届出数は16,240件（結核-12）で、同年の年報の新登録患者10,051人＋潜在性結核感染症の新登録5,967人に近い。速報値は後日修正されることがある。
A24: 年代別（2025年）
A25: 区分 | B25: 新登録患者数 | C25: 構成比(%) | D25: 罹患率（人口10万対） | E25: 出典ID
A26: 総数 | B26: 9899 | C26: 100 | D26: 8 | E26: 結核-1
A27: 0〜4歳 | B27: 16 | C27: 0.2 | D27: 0.4 | E27: 結核-1
A28: 5〜9歳 | B28: 9 | C28: 0.1 | D28: 0.2 | E28: 結核-1
A29: 10〜14歳 | B29: 6 | C29: 0.1 | D29: 0.1 | E29: 結核-1
A30: 15〜19歳 | B30: 115 | C30: 1.2 | D30: 2.1 | E30: 結核-1
A31: 20〜29歳 | B31: 1627 | C31: 16.4 | D31: 12.8 | E31: 結核-1
A32: 30〜39歳 | B32: 574 | C32: 5.8 | D32: 4.4 | E32: 結核-1
A33: 40〜49歳 | B33: 457 | C33: 4.6 | D33: 2.9 | E33: 結核-1
A34: 50〜59歳 | B34: 657 | C34: 6.6 | D34: 3.6 | E34: 結核-1
A35: 60〜69歳 | B35: 761 | C35: 7.7 | D35: 5.1 | E35: 結核-1
A36: 70〜79歳 | B36: 1640 | C36: 16.6 | D36: 10.2 | E36: 結核-1
A37: 80〜89歳 | B37: 2705 | C37: 27.3 | D37: 27.1 | E37: 結核-1
A38: 90歳以上 | B38: 1332 | C38: 13.5 | D38: 47.1 | E38: 結核-1
A40: 都道府県別 上位5（2025年、罹患率の多い順）
A41: 区分 | B41: 順位 | C41: 罹患率（人口10万対） | D41: 人数 | E41: 出典ID
A42: 大阪府 | B42: 1 | C42: 13.4 | D42: 1172 | E42: 結核-1
A43: 徳島県 | B43: 2 | C43: 10.5 | D43: 71 | E43: 結核-1
A44: 岐阜県 | B44: 3 | C44: 10.4 | D44: 196 | E44: 結核-1
...

Sheet 見るときの注意
A1: 数字を見るときの注意
A3: 全体にかかわること
A4: 1 | B4: ここにある数は、医師が保健所に届け出た数です（結核は、保健所に新しく登録された患者の数）。検査を受けていない人や、感染に気づいていない人は含まれないため、実際に感染している人の数とは同じではありません。
A5: 2 | B5: 「確定値」は、国が1年分の届出を集計し直した数です。「速報値」は、毎週や3か月ごとに出る途中の数で、あとから届出が追加されて変わることがあります。たとえば梅毒の2024年は、速報値14,663例が確定値では14,829例になりました。
A6: 3 | B6: 最新の確定値が出ている年は病気ごとに違います。HIV/エイズと結核は2025年、梅毒とはしかは2024年までです（2025年は速報値）。
A7: 4 | B7: 「2026年の途中経過」は、病気によって期間が違います。HIV/エイズは1〜6月ごろ（第1・第2四半期）、梅毒・はしか・結核は10月11日（第41週）までで、それぞれ前の年の同じ時期と比べています。
A8: 5 | B8: 出典は国の公式資料（厚生労働省、国立健康危機管理研究機構）だけを使いました。ただしHIV/エイズの年報は、厚生労働省のページから案内されている「エイズ予防情報ネット」（国の委託先）に置かれているものを使っています。HIV/エイズの「世界の動向」だけは、国連の機関（UNAIDS・IOM）の公式資料を使っています。「公費で受けられる支え」のうち結核の医療費助成の一部は、東京都の公式ページで確かめました。
A9: 6 | B9: 前年比や「10年前と比べて何倍か」などは、資料の数字からこのまとめで計算したものです。
A11: HIV/エイズ
A12: 1 | B12: 年は「報告された年」で、診断された年ではありません。
A13: 2 | B13: 2016〜2022年の合計は、HIV感染者とエイズ患者の数を足したものです（2023年以降は資料に合計が書かれています）。
A14: 3 | B14: 2024年は、速報値（合計1,000件）が確定値では994件に直されました。
A15: 4 | B15: 感染経路の「その他」は、2019年に届出用紙が変わって中身が変わったため、それより前の年とは比べにくくなっています。
A16: 5 | B16: 2025年の検査件数は、郵送検査を含まない106,756件を使いました。2025年9月から郵送検査も数えるようになったため、過去の年と比べるときは郵送を除く必要があります。
A17: 6 | B17: 厚生労働省の「HIVとエイズ」のページは、2026年10月26日時点でまだ2024年の数字のままでした。
A19: HIV/エイズ（世界）
A20: 1 | B20: UNAIDSの数字は計算で出した推計で、幅があります（例：世界で感染している人は3,530万〜4,750万人）。ページでは真ん中の値を載せています。
A21: 2 | B21: 日本の数字（このページの「HIV/エイズ」の届出数）は「その年に新しく報告された数」で、UNAIDSの「1年間に新たに感染した人（推計）」とは数え方が違うため、そのまま比べられません。
A22: 3 | B22: UNAIDSのデータ（AIDSinfo）では、日本の推計値は空欄で、公表されていません。
A23: 4 | B23: 「<100」「<500」などは、人数が少ないため「100人未満」のように幅で示された値です。感染している人が少ない国（モンゴル・ブータンなど）は、わずかな人数の変化でも2010年比の％が大きく動きます。
A24: 5 | B24: ここに載せた数字は国全体の推計です。日本に来て働く人や暮らす人のHIVの状況を表すものではありません。
A25: 6 | B25: ウズベキスタンは、新たな感染とエイズによる死亡の推計がUNAIDSに載っていません。パキスタン・フィジー・モンゴル・キルギスは「ウイルスが抑えられている人」の割合が載っていません。
A27: 梅毒
A28: 1 | B28: 2025年の確定値は、国の予定では2027年2月ごろに公表されます。このため2025年は速報値です。
A29: 2 | B29: 2025年（速報）の男女別は、厚生労働省のページのグラフに書かれた数字を読み取ったものです。
A30: 3 | B30: 性別がわからない人が1〜2人いる年があるため、男女を足しても合計と合わない年があります（2022年・2024年・2025年）。
A31: 4 | B31: 都道府県の人口10万人あたりの数は、資料に書かれている東京都と大阪府だけ載せています。
A33: はしか
A34: 1 | B34: 2025年の確定値は、2026年10月26日時点でまだ公表されていません。2025年は速報値です。
A35: 2 | B35: 2024年のワクチン接種歴別は、確定値の集計表に区分がないため、国の専門誌（IASR、2025年5月8日時点）の数字を使いました。
A36: 3 | B36: 都道府県の人口あたりの数は、確定値の集計表にないため載せていません。
A37: 4 | B37: 2回接種した人の届出もありますが、若い世代はもともと2回接種した人が多いため、人数だけでワクチンの効果は比べられません。
A39: 結核
A40: 1 | B40: 男女別の新登録患者数は、厚生労働省の年報に表がないため載せていません。
A41: 2 | B41: 「2026年の途中経過」は医師の届出の数（速報）で、発病していないが治療が必要な感染者（潜在性結核感染症）なども含みます。年報の「新登録患者数」とは数え方が違うため、直接は比べられません。
A42: 3 | B42: 80歳以上・70歳以上の割合は、年代別の数字を足して計算したものです。
A43: 4 | B43: 年報のPDFには公表日の記載がないため、出典にはファイルの更新日（2026年10月2日）を書いています。
A44: 5 | B44: 結核による死亡数は、2017年から死因の分け方が変わっていて、その影響を含みます。
A46: 公費で受けられる支え
A47: 1 | B47: ここにある制度は2026年10月26日時点のものです。申請のしかたや細かい条件は、住んでいる地域の保健所や市区町村の窓口で確かめてください。
...

Sheet 出典一覧
A1: 出典一覧（国・東京都・国連機関の公式資料のみ）
A2: 各シートの「出典ID」はこの表の番号です。URLはクリックで開けます。確認日は2026年10月26日。
A4: 出典ID | B4: 病気 | C4: 資料名 | D4: 発行元 | E4: URL | F4: 公表日・更新日 | G4: 確認日
A5: HIV-1 | B5: HIV/エイズ | C5: 第167回エイズ動向委員会 委員長コメント《令和7年 HIV感染者・エイズ患者の年間新規報告数（確定値）》 | D5: 厚生労働省エイズ動向委員会（エイズ予防情報ネット掲載） | E5: https://api-net.jfap.or.jp/status/japan/data/2026/2609/20260916_coment_kak.pdf | F5: 2026-09-16 | G5: 2026-10-26
A6: HIV-2 | B6: HIV/エイズ | C6: 令和7（2025）年エイズ発生動向 －概要－ | D6: 厚生労働省エイズ動向委員会（エイズ予防情報ネット掲載） | E6: https://api-net.jfap.or.jp/status/japan/data/2025/nenpo/r07gaiyo.pdf | F6: 2026-09-16 | G6: 2026-10-26
A7: HIV-3 | B7: HIV/エイズ | C7: 令和7年エイズ発生動向年報 表1 令和7（2025）年に報告されたHIV感染者及びAIDS患者の内訳 | D7: 厚生労働省エイズ動向委員会（エイズ予防情報ネット掲載） | E7: https://api-net.jfap.or.jp/status/japan/data/2025/nenpo/hyo-01.pdf | F7: 2026-09-16 | G7: 2026-10-26
A8: HIV-4 | B8: HIV/エイズ | C8: 令和7年エイズ発生動向年報 表3-1 HIV感染者及びAIDS患者の年次推移（国籍別、性別） | D8: 厚生労働省エイズ動向委員会（エイズ予防情報ネット掲載） | E8: https://api-net.jfap.or.jp/status/japan/data/2025/nenpo/hyo-03.pdf | F8: 2026-09-16 | G8: 2026-10-26
A9: HIV-5 | B9: HIV/エイズ | C9: 令和7年エイズ発生動向年報 表6-1 年齢階級別年次推移（HIV感染者、AIDS患者） | D9: 厚生労働省エイズ動向委員会（エイズ予防情報ネット掲載） | E9: https://api-net.jfap.or.jp/status/japan/data/2025/nenpo/hyo-061.pdf | F9: 2026-09-16 | G9: 2026-10-26
A10: HIV-6 | B10: HIV/エイズ | C10: 令和7年エイズ発生動向年報 表10-1 報告地別年次推移及び累計等（HIV感染者・合計） | D10: 厚生労働省エイズ動向委員会（エイズ予防情報ネット掲載） | E10: https://api-net.jfap.or.jp/status/japan/data/2025/nenpo/hyo-101.pdf | F10: 2026-09-16 | G10: 2026-10-26
A11: HIV-7 | B11: HIV/エイズ | C11: 令和7年エイズ発生動向年報 表10-4 報告地別年次推移及び累計等（AIDS患者・合計） | D11: 厚生労働省エイズ動向委員会（エイズ予防情報ネット掲載） | E11: https://api-net.jfap.or.jp/status/japan/data/2025/nenpo/hyo-104.pdf | F11: 2026-09-16 | G11: 2026-10-26
A12: HIV-8 | B12: HIV/エイズ | C12: 令和7年エイズ発生動向年報（参考）保健所等におけるHIV抗体検査及びHIV郵送検査件数 | D12: 厚生労働省エイズ動向委員会（エイズ予防情報ネット掲載） | E12: https://api-net.jfap.or.jp/status/japan/data/2025/nenpo/kensa.pdf | F12: 2026-09-16 | G12: 2026-10-26
A13: HIV-9 | B13: HIV/エイズ | C13: 令和7年エイズ発生動向年報（参考）保健所等における相談件数 | D13: 厚生労働省エイズ動向委員会（エイズ予防情報ネット掲載） | E13: https://api-net.jfap.or.jp/status/japan/data/2025/nenpo/soudan.pdf | F13: 2026-09-16 | G13: 2026-10-26
A14: HIV-10 | B14: HIV/エイズ | C14: 第167回エイズ動向委員会 委員長コメント《R8年 第1・2四半期》 | D14: 厚生労働省エイズ動向委員会（エイズ予防情報ネット掲載） | E14: https://api-net.jfap.or.jp/status/japan/data/2026/2609/20260916_coment.pdf | F14: 2026-09-16 | G14: 2026-10-26
A15: HIV-11 | B15: HIV/エイズ | C15: 令和8年第1・第2四半期 エイズ動向委員会報告 資料（Excel：表1-1Q・表1-2Q・表2 累計ほか） | D15: 厚生労働省エイズ動向委員会（エイズ予防情報ネット掲載） | E15: https://api-net.jfap.or.jp/status/japan/data/2026/2609/20260916.xlsx | F15: 2026-09-16 | G15: 2026-10-26
... A83: 公費-9 | B83: 公費の制度 | C83: 麻しん及び風しんの定期の予防接種に係る対応について（事務連絡） | D83: 厚生労働省 健康・生活衛生局感染症対策部予防接種課 | E83: https://www.mhlw.go.jp/content/10900000/001440529.pdf | F83: 2025-03-11 | G83: 2026-10-26
